{
 "cells": [
  {
   "cell_type": "code",
   "execution_count": 1,
   "metadata": {},
   "outputs": [
    {
     "name": "stderr",
     "output_type": "stream",
     "text": [
      "Using TensorFlow backend.\n"
     ]
    }
   ],
   "source": [
    "import os\n",
    "from IPython.display import Video\n",
    "import pandas as pd\n",
    "import numpy as np\n",
    "from imageai.Detection import VideoObjectDetection\n",
    "from imageai.Detection import cv2"
   ]
  },
  {
   "cell_type": "code",
   "execution_count": 2,
   "metadata": {},
   "outputs": [
    {
     "name": "stdout",
     "output_type": "stream",
     "text": [
      "WARNING:tensorflow:From C:\\Users\\serge\\Anaconda3\\envs\\KerasEnv\\lib\\site-packages\\tensorflow\\python\\framework\\op_def_library.py:263: colocate_with (from tensorflow.python.framework.ops) is deprecated and will be removed in a future version.\n",
      "Instructions for updating:\n",
      "Colocations handled automatically by placer.\n"
     ]
    }
   ],
   "source": [
    "path = 'yolo.h5'\n",
    "detector = VideoObjectDetection()\n",
    "detector.setModelTypeAsYOLOv3()\n",
    "detector.setModelPath(path)\n",
    "detector.loadModel()"
   ]
  },
  {
   "cell_type": "code",
   "execution_count": 3,
   "metadata": {},
   "outputs": [],
   "source": [
    "filename = 'sm.avi'\n",
    "resultfile = 'sm_result.avi'"
   ]
  },
  {
   "cell_type": "code",
   "execution_count": 4,
   "metadata": {
    "scrolled": true
   },
   "outputs": [
    {
     "name": "stdout",
     "output_type": "stream",
     "text": [
      "Processing Frame :  1\n"
     ]
    },
    {
     "ename": "ValueError",
     "evalue": "An error occured. It may be that your input video is invalid. Ensure you specified a proper string value for 'output_file_path' is 'save_detected_video' is not False. Also ensure your per_frame, per_second, per_minute or video_complete_analysis function is properly configured to receive the right parameters. ",
     "output_type": "error",
     "traceback": [
      "\u001b[1;31m---------------------------------------------------------------------------\u001b[0m",
      "\u001b[1;31mUnknownError\u001b[0m                              Traceback (most recent call last)",
      "\u001b[1;32m~\\Anaconda3\\envs\\KerasEnv\\lib\\site-packages\\tensorflow\\python\\client\\session.py\u001b[0m in \u001b[0;36m_do_call\u001b[1;34m(self, fn, *args)\u001b[0m\n\u001b[0;32m   1333\u001b[0m     \u001b[1;32mtry\u001b[0m\u001b[1;33m:\u001b[0m\u001b[1;33m\u001b[0m\u001b[1;33m\u001b[0m\u001b[0m\n\u001b[1;32m-> 1334\u001b[1;33m       \u001b[1;32mreturn\u001b[0m \u001b[0mfn\u001b[0m\u001b[1;33m(\u001b[0m\u001b[1;33m*\u001b[0m\u001b[0margs\u001b[0m\u001b[1;33m)\u001b[0m\u001b[1;33m\u001b[0m\u001b[1;33m\u001b[0m\u001b[0m\n\u001b[0m\u001b[0;32m   1335\u001b[0m     \u001b[1;32mexcept\u001b[0m \u001b[0merrors\u001b[0m\u001b[1;33m.\u001b[0m\u001b[0mOpError\u001b[0m \u001b[1;32mas\u001b[0m \u001b[0me\u001b[0m\u001b[1;33m:\u001b[0m\u001b[1;33m\u001b[0m\u001b[1;33m\u001b[0m\u001b[0m\n",
      "\u001b[1;32m~\\Anaconda3\\envs\\KerasEnv\\lib\\site-packages\\tensorflow\\python\\client\\session.py\u001b[0m in \u001b[0;36m_run_fn\u001b[1;34m(feed_dict, fetch_list, target_list, options, run_metadata)\u001b[0m\n\u001b[0;32m   1318\u001b[0m       return self._call_tf_sessionrun(\n\u001b[1;32m-> 1319\u001b[1;33m           options, feed_dict, fetch_list, target_list, run_metadata)\n\u001b[0m\u001b[0;32m   1320\u001b[0m \u001b[1;33m\u001b[0m\u001b[0m\n",
      "\u001b[1;32m~\\Anaconda3\\envs\\KerasEnv\\lib\\site-packages\\tensorflow\\python\\client\\session.py\u001b[0m in \u001b[0;36m_call_tf_sessionrun\u001b[1;34m(self, options, feed_dict, fetch_list, target_list, run_metadata)\u001b[0m\n\u001b[0;32m   1406\u001b[0m         \u001b[0mself\u001b[0m\u001b[1;33m.\u001b[0m\u001b[0m_session\u001b[0m\u001b[1;33m,\u001b[0m \u001b[0moptions\u001b[0m\u001b[1;33m,\u001b[0m \u001b[0mfeed_dict\u001b[0m\u001b[1;33m,\u001b[0m \u001b[0mfetch_list\u001b[0m\u001b[1;33m,\u001b[0m \u001b[0mtarget_list\u001b[0m\u001b[1;33m,\u001b[0m\u001b[1;33m\u001b[0m\u001b[1;33m\u001b[0m\u001b[0m\n\u001b[1;32m-> 1407\u001b[1;33m         run_metadata)\n\u001b[0m\u001b[0;32m   1408\u001b[0m \u001b[1;33m\u001b[0m\u001b[0m\n",
      "\u001b[1;31mUnknownError\u001b[0m: Failed to get convolution algorithm. This is probably because cuDNN failed to initialize, so try looking to see if a warning log message was printed above.\n\t [[{{node conv2d_1/convolution}}]]\n\t [[{{node boolean_mask_120/GatherV2}}]]",
      "\nDuring handling of the above exception, another exception occurred:\n",
      "\u001b[1;31mUnknownError\u001b[0m                              Traceback (most recent call last)",
      "\u001b[1;32m~\\Anaconda3\\envs\\KerasEnv\\lib\\site-packages\\imageai\\Detection\\__init__.py\u001b[0m in \u001b[0;36mdetectObjectsFromVideo\u001b[1;34m(self, input_file_path, camera_input, output_file_path, frames_per_second, frame_detection_interval, minimum_percentage_probability, log_progress, display_percentage_probability, display_object_name, save_detected_video, per_frame_function, per_second_function, per_minute_function, video_complete_function, return_detected_frame, detection_timeout)\u001b[0m\n\u001b[0;32m   1511\u001b[0m                                         \u001b[0mself\u001b[0m\u001b[1;33m.\u001b[0m\u001b[0m__yolo_input_image_shape\u001b[0m\u001b[1;33m:\u001b[0m \u001b[1;33m[\u001b[0m\u001b[0mframe\u001b[0m\u001b[1;33m.\u001b[0m\u001b[0msize\u001b[0m\u001b[1;33m[\u001b[0m\u001b[1;36m1\u001b[0m\u001b[1;33m]\u001b[0m\u001b[1;33m,\u001b[0m \u001b[0mframe\u001b[0m\u001b[1;33m.\u001b[0m\u001b[0msize\u001b[0m\u001b[1;33m[\u001b[0m\u001b[1;36m0\u001b[0m\u001b[1;33m]\u001b[0m\u001b[1;33m]\u001b[0m\u001b[1;33m,\u001b[0m\u001b[1;33m\u001b[0m\u001b[1;33m\u001b[0m\u001b[0m\n\u001b[1;32m-> 1512\u001b[1;33m                                         \u001b[0mK\u001b[0m\u001b[1;33m.\u001b[0m\u001b[0mlearning_phase\u001b[0m\u001b[1;33m(\u001b[0m\u001b[1;33m)\u001b[0m\u001b[1;33m:\u001b[0m \u001b[1;36m0\u001b[0m\u001b[1;33m\u001b[0m\u001b[1;33m\u001b[0m\u001b[0m\n\u001b[0m\u001b[0;32m   1513\u001b[0m                                     })\n",
      "\u001b[1;32m~\\Anaconda3\\envs\\KerasEnv\\lib\\site-packages\\tensorflow\\python\\client\\session.py\u001b[0m in \u001b[0;36mrun\u001b[1;34m(self, fetches, feed_dict, options, run_metadata)\u001b[0m\n\u001b[0;32m    928\u001b[0m       result = self._run(None, fetches, feed_dict, options_ptr,\n\u001b[1;32m--> 929\u001b[1;33m                          run_metadata_ptr)\n\u001b[0m\u001b[0;32m    930\u001b[0m       \u001b[1;32mif\u001b[0m \u001b[0mrun_metadata\u001b[0m\u001b[1;33m:\u001b[0m\u001b[1;33m\u001b[0m\u001b[1;33m\u001b[0m\u001b[0m\n",
      "\u001b[1;32m~\\Anaconda3\\envs\\KerasEnv\\lib\\site-packages\\tensorflow\\python\\client\\session.py\u001b[0m in \u001b[0;36m_run\u001b[1;34m(self, handle, fetches, feed_dict, options, run_metadata)\u001b[0m\n\u001b[0;32m   1151\u001b[0m       results = self._do_run(handle, final_targets, final_fetches,\n\u001b[1;32m-> 1152\u001b[1;33m                              feed_dict_tensor, options, run_metadata)\n\u001b[0m\u001b[0;32m   1153\u001b[0m     \u001b[1;32melse\u001b[0m\u001b[1;33m:\u001b[0m\u001b[1;33m\u001b[0m\u001b[1;33m\u001b[0m\u001b[0m\n",
      "\u001b[1;32m~\\Anaconda3\\envs\\KerasEnv\\lib\\site-packages\\tensorflow\\python\\client\\session.py\u001b[0m in \u001b[0;36m_do_run\u001b[1;34m(self, handle, target_list, fetch_list, feed_dict, options, run_metadata)\u001b[0m\n\u001b[0;32m   1327\u001b[0m       return self._do_call(_run_fn, feeds, fetches, targets, options,\n\u001b[1;32m-> 1328\u001b[1;33m                            run_metadata)\n\u001b[0m\u001b[0;32m   1329\u001b[0m     \u001b[1;32melse\u001b[0m\u001b[1;33m:\u001b[0m\u001b[1;33m\u001b[0m\u001b[1;33m\u001b[0m\u001b[0m\n",
      "\u001b[1;32m~\\Anaconda3\\envs\\KerasEnv\\lib\\site-packages\\tensorflow\\python\\client\\session.py\u001b[0m in \u001b[0;36m_do_call\u001b[1;34m(self, fn, *args)\u001b[0m\n\u001b[0;32m   1347\u001b[0m       \u001b[0mmessage\u001b[0m \u001b[1;33m=\u001b[0m \u001b[0merror_interpolation\u001b[0m\u001b[1;33m.\u001b[0m\u001b[0minterpolate\u001b[0m\u001b[1;33m(\u001b[0m\u001b[0mmessage\u001b[0m\u001b[1;33m,\u001b[0m \u001b[0mself\u001b[0m\u001b[1;33m.\u001b[0m\u001b[0m_graph\u001b[0m\u001b[1;33m)\u001b[0m\u001b[1;33m\u001b[0m\u001b[1;33m\u001b[0m\u001b[0m\n\u001b[1;32m-> 1348\u001b[1;33m       \u001b[1;32mraise\u001b[0m \u001b[0mtype\u001b[0m\u001b[1;33m(\u001b[0m\u001b[0me\u001b[0m\u001b[1;33m)\u001b[0m\u001b[1;33m(\u001b[0m\u001b[0mnode_def\u001b[0m\u001b[1;33m,\u001b[0m \u001b[0mop\u001b[0m\u001b[1;33m,\u001b[0m \u001b[0mmessage\u001b[0m\u001b[1;33m)\u001b[0m\u001b[1;33m\u001b[0m\u001b[1;33m\u001b[0m\u001b[0m\n\u001b[0m\u001b[0;32m   1349\u001b[0m \u001b[1;33m\u001b[0m\u001b[0m\n",
      "\u001b[1;31mUnknownError\u001b[0m: Failed to get convolution algorithm. This is probably because cuDNN failed to initialize, so try looking to see if a warning log message was printed above.\n\t [[node conv2d_1/convolution (defined at C:\\Users\\serge\\Anaconda3\\envs\\KerasEnv\\lib\\site-packages\\keras\\backend\\tensorflow_backend.py:3650) ]]\n\t [[node boolean_mask_120/GatherV2 (defined at C:\\Users\\serge\\Anaconda3\\envs\\KerasEnv\\lib\\site-packages\\imageai\\Detection\\YOLOv3\\utils.py:99) ]]\n\nCaused by op 'conv2d_1/convolution', defined at:\n  File \"C:\\Users\\serge\\Anaconda3\\envs\\KerasEnv\\lib\\runpy.py\", line 193, in _run_module_as_main\n    \"__main__\", mod_spec)\n  File \"C:\\Users\\serge\\Anaconda3\\envs\\KerasEnv\\lib\\runpy.py\", line 85, in _run_code\n    exec(code, run_globals)\n  File \"C:\\Users\\serge\\Anaconda3\\envs\\KerasEnv\\lib\\site-packages\\ipykernel_launcher.py\", line 16, in <module>\n    app.launch_new_instance()\n  File \"C:\\Users\\serge\\Anaconda3\\envs\\KerasEnv\\lib\\site-packages\\traitlets\\config\\application.py\", line 658, in launch_instance\n    app.start()\n  File \"C:\\Users\\serge\\Anaconda3\\envs\\KerasEnv\\lib\\site-packages\\ipykernel\\kernelapp.py\", line 505, in start\n    self.io_loop.start()\n  File \"C:\\Users\\serge\\Anaconda3\\envs\\KerasEnv\\lib\\site-packages\\tornado\\platform\\asyncio.py\", line 148, in start\n    self.asyncio_loop.run_forever()\n  File \"C:\\Users\\serge\\Anaconda3\\envs\\KerasEnv\\lib\\asyncio\\base_events.py\", line 539, in run_forever\n    self._run_once()\n  File \"C:\\Users\\serge\\Anaconda3\\envs\\KerasEnv\\lib\\asyncio\\base_events.py\", line 1775, in _run_once\n    handle._run()\n  File \"C:\\Users\\serge\\Anaconda3\\envs\\KerasEnv\\lib\\asyncio\\events.py\", line 88, in _run\n    self._context.run(self._callback, *self._args)\n  File \"C:\\Users\\serge\\Anaconda3\\envs\\KerasEnv\\lib\\site-packages\\tornado\\ioloop.py\", line 690, in <lambda>\n    lambda f: self._run_callback(functools.partial(callback, future))\n  File \"C:\\Users\\serge\\Anaconda3\\envs\\KerasEnv\\lib\\site-packages\\tornado\\ioloop.py\", line 743, in _run_callback\n    ret = callback()\n  File \"C:\\Users\\serge\\Anaconda3\\envs\\KerasEnv\\lib\\site-packages\\tornado\\gen.py\", line 787, in inner\n    self.run()\n  File \"C:\\Users\\serge\\Anaconda3\\envs\\KerasEnv\\lib\\site-packages\\tornado\\gen.py\", line 748, in run\n    yielded = self.gen.send(value)\n  File \"C:\\Users\\serge\\Anaconda3\\envs\\KerasEnv\\lib\\site-packages\\ipykernel\\kernelbase.py\", line 378, in dispatch_queue\n    yield self.process_one()\n  File \"C:\\Users\\serge\\Anaconda3\\envs\\KerasEnv\\lib\\site-packages\\tornado\\gen.py\", line 225, in wrapper\n    runner = Runner(result, future, yielded)\n  File \"C:\\Users\\serge\\Anaconda3\\envs\\KerasEnv\\lib\\site-packages\\tornado\\gen.py\", line 714, in __init__\n    self.run()\n  File \"C:\\Users\\serge\\Anaconda3\\envs\\KerasEnv\\lib\\site-packages\\tornado\\gen.py\", line 748, in run\n    yielded = self.gen.send(value)\n  File \"C:\\Users\\serge\\Anaconda3\\envs\\KerasEnv\\lib\\site-packages\\ipykernel\\kernelbase.py\", line 365, in process_one\n    yield gen.maybe_future(dispatch(*args))\n  File \"C:\\Users\\serge\\Anaconda3\\envs\\KerasEnv\\lib\\site-packages\\tornado\\gen.py\", line 209, in wrapper\n    yielded = next(result)\n  File \"C:\\Users\\serge\\Anaconda3\\envs\\KerasEnv\\lib\\site-packages\\ipykernel\\kernelbase.py\", line 272, in dispatch_shell\n    yield gen.maybe_future(handler(stream, idents, msg))\n  File \"C:\\Users\\serge\\Anaconda3\\envs\\KerasEnv\\lib\\site-packages\\tornado\\gen.py\", line 209, in wrapper\n    yielded = next(result)\n  File \"C:\\Users\\serge\\Anaconda3\\envs\\KerasEnv\\lib\\site-packages\\ipykernel\\kernelbase.py\", line 542, in execute_request\n    user_expressions, allow_stdin,\n  File \"C:\\Users\\serge\\Anaconda3\\envs\\KerasEnv\\lib\\site-packages\\tornado\\gen.py\", line 209, in wrapper\n    yielded = next(result)\n  File \"C:\\Users\\serge\\Anaconda3\\envs\\KerasEnv\\lib\\site-packages\\ipykernel\\ipkernel.py\", line 294, in do_execute\n    res = shell.run_cell(code, store_history=store_history, silent=silent)\n  File \"C:\\Users\\serge\\Anaconda3\\envs\\KerasEnv\\lib\\site-packages\\ipykernel\\zmqshell.py\", line 536, in run_cell\n    return super(ZMQInteractiveShell, self).run_cell(*args, **kwargs)\n  File \"C:\\Users\\serge\\Anaconda3\\envs\\KerasEnv\\lib\\site-packages\\IPython\\core\\interactiveshell.py\", line 2854, in run_cell\n    raw_cell, store_history, silent, shell_futures)\n  File \"C:\\Users\\serge\\Anaconda3\\envs\\KerasEnv\\lib\\site-packages\\IPython\\core\\interactiveshell.py\", line 2880, in _run_cell\n    return runner(coro)\n  File \"C:\\Users\\serge\\Anaconda3\\envs\\KerasEnv\\lib\\site-packages\\IPython\\core\\async_helpers.py\", line 68, in _pseudo_sync_runner\n    coro.send(None)\n  File \"C:\\Users\\serge\\Anaconda3\\envs\\KerasEnv\\lib\\site-packages\\IPython\\core\\interactiveshell.py\", line 3057, in run_cell_async\n    interactivity=interactivity, compiler=compiler, result=result)\n  File \"C:\\Users\\serge\\Anaconda3\\envs\\KerasEnv\\lib\\site-packages\\IPython\\core\\interactiveshell.py\", line 3248, in run_ast_nodes\n    if (await self.run_code(code, result,  async_=asy)):\n  File \"C:\\Users\\serge\\Anaconda3\\envs\\KerasEnv\\lib\\site-packages\\IPython\\core\\interactiveshell.py\", line 3325, in run_code\n    exec(code_obj, self.user_global_ns, self.user_ns)\n  File \"<ipython-input-2-9742dfd89102>\", line 5, in <module>\n    detector.loadModel()\n  File \"C:\\Users\\serge\\Anaconda3\\envs\\KerasEnv\\lib\\site-packages\\imageai\\Detection\\__init__.py\", line 1054, in loadModel\n    len(self.numbers_to_names))\n  File \"C:\\Users\\serge\\Anaconda3\\envs\\KerasEnv\\lib\\site-packages\\imageai\\Detection\\YOLOv3\\models.py\", line 60, in yolo_main\n    darknet_network = Model(input, darknet(input))\n  File \"C:\\Users\\serge\\Anaconda3\\envs\\KerasEnv\\lib\\site-packages\\imageai\\Detection\\YOLOv3\\models.py\", line 33, in darknet\n    network = NetworkConv2D_BN_Leaky(input=input, channels=32, kernel_size=(3,3))\n  File \"C:\\Users\\serge\\Anaconda3\\envs\\KerasEnv\\lib\\site-packages\\imageai\\Detection\\YOLOv3\\models.py\", line 16, in NetworkConv2D_BN_Leaky\n    network = Conv2D( filters=channels, kernel_size=kernel_size, strides=strides, padding=padding, kernel_regularizer=kernel_regularizer, use_bias=use_bias)(input)\n  File \"C:\\Users\\serge\\Anaconda3\\envs\\KerasEnv\\lib\\site-packages\\keras\\engine\\base_layer.py\", line 457, in __call__\n    output = self.call(inputs, **kwargs)\n  File \"C:\\Users\\serge\\Anaconda3\\envs\\KerasEnv\\lib\\site-packages\\keras\\layers\\convolutional.py\", line 171, in call\n    dilation_rate=self.dilation_rate)\n  File \"C:\\Users\\serge\\Anaconda3\\envs\\KerasEnv\\lib\\site-packages\\keras\\backend\\tensorflow_backend.py\", line 3650, in conv2d\n    data_format=tf_data_format)\n  File \"C:\\Users\\serge\\Anaconda3\\envs\\KerasEnv\\lib\\site-packages\\tensorflow\\python\\ops\\nn_ops.py\", line 851, in convolution\n    return op(input, filter)\n  File \"C:\\Users\\serge\\Anaconda3\\envs\\KerasEnv\\lib\\site-packages\\tensorflow\\python\\ops\\nn_ops.py\", line 966, in __call__\n    return self.conv_op(inp, filter)\n  File \"C:\\Users\\serge\\Anaconda3\\envs\\KerasEnv\\lib\\site-packages\\tensorflow\\python\\ops\\nn_ops.py\", line 591, in __call__\n    return self.call(inp, filter)\n  File \"C:\\Users\\serge\\Anaconda3\\envs\\KerasEnv\\lib\\site-packages\\tensorflow\\python\\ops\\nn_ops.py\", line 208, in __call__\n    name=self.name)\n  File \"C:\\Users\\serge\\Anaconda3\\envs\\KerasEnv\\lib\\site-packages\\tensorflow\\python\\ops\\gen_nn_ops.py\", line 1026, in conv2d\n    data_format=data_format, dilations=dilations, name=name)\n  File \"C:\\Users\\serge\\Anaconda3\\envs\\KerasEnv\\lib\\site-packages\\tensorflow\\python\\framework\\op_def_library.py\", line 788, in _apply_op_helper\n    op_def=op_def)\n  File \"C:\\Users\\serge\\Anaconda3\\envs\\KerasEnv\\lib\\site-packages\\tensorflow\\python\\util\\deprecation.py\", line 507, in new_func\n    return func(*args, **kwargs)\n  File \"C:\\Users\\serge\\Anaconda3\\envs\\KerasEnv\\lib\\site-packages\\tensorflow\\python\\framework\\ops.py\", line 3300, in create_op\n    op_def=op_def)\n  File \"C:\\Users\\serge\\Anaconda3\\envs\\KerasEnv\\lib\\site-packages\\tensorflow\\python\\framework\\ops.py\", line 1801, in __init__\n    self._traceback = tf_stack.extract_stack()\n\nUnknownError (see above for traceback): Failed to get convolution algorithm. This is probably because cuDNN failed to initialize, so try looking to see if a warning log message was printed above.\n\t [[node conv2d_1/convolution (defined at C:\\Users\\serge\\Anaconda3\\envs\\KerasEnv\\lib\\site-packages\\keras\\backend\\tensorflow_backend.py:3650) ]]\n\t [[node boolean_mask_120/GatherV2 (defined at C:\\Users\\serge\\Anaconda3\\envs\\KerasEnv\\lib\\site-packages\\imageai\\Detection\\YOLOv3\\utils.py:99) ]]\n",
      "\nDuring handling of the above exception, another exception occurred:\n",
      "\u001b[1;31mValueError\u001b[0m                                Traceback (most recent call last)",
      "\u001b[1;32m<ipython-input-4-7543ec1f3124>\u001b[0m in \u001b[0;36m<module>\u001b[1;34m\u001b[0m\n\u001b[1;32m----> 1\u001b[1;33m \u001b[0mvideo_path\u001b[0m \u001b[1;33m=\u001b[0m \u001b[0mdetector\u001b[0m\u001b[1;33m.\u001b[0m\u001b[0mdetectObjectsFromVideo\u001b[0m\u001b[1;33m(\u001b[0m\u001b[0minput_file_path\u001b[0m\u001b[1;33m=\u001b[0m\u001b[0mfilename\u001b[0m\u001b[1;33m,\u001b[0m\u001b[0moutput_file_path\u001b[0m\u001b[1;33m=\u001b[0m\u001b[0mresultfile\u001b[0m\u001b[1;33m,\u001b[0m\u001b[0mframes_per_second\u001b[0m\u001b[1;33m=\u001b[0m\u001b[1;36m25\u001b[0m\u001b[1;33m,\u001b[0m\u001b[0mlog_progress\u001b[0m\u001b[1;33m=\u001b[0m\u001b[1;32mTrue\u001b[0m\u001b[1;33m,\u001b[0m\u001b[0mminimum_percentage_probability\u001b[0m\u001b[1;33m=\u001b[0m\u001b[1;36m30\u001b[0m\u001b[1;33m,\u001b[0m\u001b[0mdisplay_percentage_probability\u001b[0m\u001b[1;33m=\u001b[0m\u001b[1;32mTrue\u001b[0m\u001b[1;33m,\u001b[0m\u001b[0mdisplay_object_name\u001b[0m\u001b[1;33m=\u001b[0m\u001b[1;32mTrue\u001b[0m\u001b[1;33m,\u001b[0m\u001b[0msave_detected_video\u001b[0m\u001b[1;33m=\u001b[0m\u001b[1;32mTrue\u001b[0m\u001b[1;33m)\u001b[0m\u001b[1;33m\u001b[0m\u001b[1;33m\u001b[0m\u001b[0m\n\u001b[0m",
      "\u001b[1;32m~\\Anaconda3\\envs\\KerasEnv\\lib\\site-packages\\imageai\\Detection\\__init__.py\u001b[0m in \u001b[0;36mdetectObjectsFromVideo\u001b[1;34m(self, input_file_path, camera_input, output_file_path, frames_per_second, frame_detection_interval, minimum_percentage_probability, log_progress, display_percentage_probability, display_object_name, save_detected_video, per_frame_function, per_second_function, per_minute_function, video_complete_function, return_detected_frame, detection_timeout)\u001b[0m\n\u001b[0;32m   1686\u001b[0m             \u001b[1;32mexcept\u001b[0m\u001b[1;33m:\u001b[0m\u001b[1;33m\u001b[0m\u001b[1;33m\u001b[0m\u001b[0m\n\u001b[0;32m   1687\u001b[0m                 raise ValueError(\n\u001b[1;32m-> 1688\u001b[1;33m                     \u001b[1;34m\"An error occured. It may be that your input video is invalid. Ensure you specified a proper string value for 'output_file_path' is 'save_detected_video' is not False. \"\u001b[0m\u001b[1;33m\u001b[0m\u001b[1;33m\u001b[0m\u001b[0m\n\u001b[0m\u001b[0;32m   1689\u001b[0m                     \"Also ensure your per_frame, per_second, per_minute or video_complete_analysis function is properly configured to receive the right parameters. \")\n\u001b[0;32m   1690\u001b[0m \u001b[1;33m\u001b[0m\u001b[0m\n",
      "\u001b[1;31mValueError\u001b[0m: An error occured. It may be that your input video is invalid. Ensure you specified a proper string value for 'output_file_path' is 'save_detected_video' is not False. Also ensure your per_frame, per_second, per_minute or video_complete_analysis function is properly configured to receive the right parameters. "
     ]
    }
   ],
   "source": [
    "video_path = detector.detectObjectsFromVideo(input_file_path=filename,output_file_path=resultfile,frames_per_second=25,log_progress=True,minimum_percentage_probability=30,display_percentage_probability=True,display_object_name=True,save_detected_video=True)\n"
   ]
  },
  {
   "cell_type": "code",
   "execution_count": null,
   "metadata": {},
   "outputs": [],
   "source": [
    "print('Tadam!!!')"
   ]
  },
  {
   "cell_type": "code",
   "execution_count": null,
   "metadata": {},
   "outputs": [],
   "source": []
  },
  {
   "cell_type": "code",
   "execution_count": null,
   "metadata": {},
   "outputs": [],
   "source": []
  }
 ],
 "metadata": {
  "kernelspec": {
   "display_name": "Python 3",
   "language": "python",
   "name": "python3"
  },
  "language_info": {
   "codemirror_mode": {
    "name": "ipython",
    "version": 3
   },
   "file_extension": ".py",
   "mimetype": "text/x-python",
   "name": "python",
   "nbconvert_exporter": "python",
   "pygments_lexer": "ipython3",
   "version": "3.7.3"
  }
 },
 "nbformat": 4,
 "nbformat_minor": 2
}
